BTC Address: 1PjKrFpoCCcwJG27gQABidUPRVJGcgGP2t
Private Key: 91722da8c7633c2fcc2c2526f892f6019ffb7d4a58fba6155d9b1861b4ebe71b
Electrum Import Key: 5JvLocwnfYHQghT1FdZw6PjbWsZVCW7GKXbrQAdMwxfgwfykKmZ
btcamount: 0
==================================================================================
Traceback (most recent call last):
  File ".\BTCL-Dev.py", line 113, in <module>
    executeScript()
  File ".\BTCL-Dev.py", line 66, in executeScript
    btcamount = re.search('final_balance":(.+?),"n_tx', text).group(1)
AttributeError: 'NoneType' object has no attribute 'group'


BTC Address: 1PjKrFpoCCcwJG27gQABidUPRVJGcgGP2t
Private Key: 91722da8c7633c2fcc2c2526f892f6019ffb7d4a58fba6155d9b1861b4ebe71b
Electrum Import Key: 5JvLocwnfYHQghT1FdZw6PjbWsZVCW7GKXbrQAdMwxfgwfykKmZ
btcamount: 0
==================================================================================
Traceback (most recent call last):
  File ".\BTCL-Dev.py", line 113, in <module>
    executeScript()
  File ".\BTCL-Dev.py", line 66, in executeScript
    btcamount = re.search('final_balance":(.+?),"n_tx', text).group(1)
AttributeError: 'NoneType' object has no attribute 'group'


================================================================================
BTC Address: 1KyX8RJGNtjUjmtWBeKoq7qecuCzRqAy8U
Private Key: 827aa2b8ce2b3e103720774c675fb6084ff12331637561df41983fa3333f6262
Electrum Import Key: 5JokVaje39aukXfjMiFrKfdNww8SHE4ffJwtCPPscap6MxYCHjd
btcamount: 0
==================================================================================
Traceback (most recent call last):
  File "C:\Users\bwn\AppData\Local\Programs\Python\Python38\lib\site-packages\urllib3\connectionpool.py", line 665, in urlopen
    httplib_response = self._make_request(
  File "C:\Users\bwn\AppData\Local\Programs\Python\Python38\lib\site-packages\urllib3\connectionpool.py", line 376, in _make_request
    self._validate_conn(conn)
  File "C:\Users\bwn\AppData\Local\Programs\Python\Python38\lib\site-packages\urllib3\connectionpool.py", line 994, in _validate_conn
    conn.connect()
  File "C:\Users\bwn\AppData\Local\Programs\Python\Python38\lib\site-packages\urllib3\connection.py", line 386, in connect
    self.sock = ssl_wrap_socket(
  File "C:\Users\bwn\AppData\Local\Programs\Python\Python38\lib\site-packages\urllib3\util\ssl_.py", line 370, in ssl_wrap_socket
    return context.wrap_socket(sock, server_hostname=server_hostname)
  File "C:\Users\bwn\AppData\Local\Programs\Python\Python38\lib\ssl.py", line 500, in wrap_socket
    return self.sslsocket_class._create(
  File "C:\Users\bwn\AppData\Local\Programs\Python\Python38\lib\ssl.py", line 1040, in _create
    self.do_handshake()
  File "C:\Users\bwn\AppData\Local\Programs\Python\Python38\lib\ssl.py", line 1309, in do_handshake
    self._sslobj.do_handshake()
ConnectionResetError: [WinError 10054] De externe host heeft een verbinding verbroken

During handling of the above exception, another exception occurred:

Traceback (most recent call last):
  File "C:\Users\bwn\AppData\Local\Programs\Python\Python38\lib\site-packages\requests\adapters.py", line 439, in send
    resp = conn.urlopen(
  File "C:\Users\bwn\AppData\Local\Programs\Python\Python38\lib\site-packages\urllib3\connectionpool.py", line 719, in urlopen
    retries = retries.increment(
  File "C:\Users\bwn\AppData\Local\Programs\Python\Python38\lib\site-packages\urllib3\util\retry.py", line 400, in increment
    raise six.reraise(type(error), error, _stacktrace)
  File "C:\Users\bwn\AppData\Local\Programs\Python\Python38\lib\site-packages\urllib3\packages\six.py", line 734, in reraise
    raise value.with_traceback(tb)
  File "C:\Users\bwn\AppData\Local\Programs\Python\Python38\lib\site-packages\urllib3\connectionpool.py", line 665, in urlopen
    httplib_response = self._make_request(
  File "C:\Users\bwn\AppData\Local\Programs\Python\Python38\lib\site-packages\urllib3\connectionpool.py", line 376, in _make_request
    self._validate_conn(conn)
  File "C:\Users\bwn\AppData\Local\Programs\Python\Python38\lib\site-packages\urllib3\connectionpool.py", line 994, in _validate_conn
    conn.connect()
  File "C:\Users\bwn\AppData\Local\Programs\Python\Python38\lib\site-packages\urllib3\connection.py", line 386, in connect
    self.sock = ssl_wrap_socket(
  File "C:\Users\bwn\AppData\Local\Programs\Python\Python38\lib\site-packages\urllib3\util\ssl_.py", line 370, in ssl_wrap_socket
    return context.wrap_socket(sock, server_hostname=server_hostname)
  File "C:\Users\bwn\AppData\Local\Programs\Python\Python38\lib\ssl.py", line 500, in wrap_socket
    return self.sslsocket_class._create(
  File "C:\Users\bwn\AppData\Local\Programs\Python\Python38\lib\ssl.py", line 1040, in _create
    self.do_handshake()
  File "C:\Users\bwn\AppData\Local\Programs\Python\Python38\lib\ssl.py", line 1309, in do_handshake
    self._sslobj.do_handshake()
urllib3.exceptions.ProtocolError: ('Connection aborted.', ConnectionResetError(10054, 'De externe host heeft een verbinding verbroken', None, 10054, None))

During handling of the above exception, another exception occurred:

Traceback (most recent call last):
  File ".\BTCL-Dev.py", line 113, in <module>
    executeScript()
  File ".\BTCL-Dev.py", line 35, in executeScript
    req = requests.get('https://blockchain.info/balance?active='+(addr))
  File "C:\Users\bwn\AppData\Local\Programs\Python\Python38\lib\site-packages\requests\api.py", line 75, in get
    return request('get', url, params=params, **kwargs)
  File "C:\Users\bwn\AppData\Local\Programs\Python\Python38\lib\site-packages\requests\api.py", line 60, in request
    return session.request(method=method, url=url, **kwargs)
  File "C:\Users\bwn\AppData\Local\Programs\Python\Python38\lib\site-packages\requests\sessions.py", line 533, in request
    resp = self.send(prep, **send_kwargs)
  File "C:\Users\bwn\AppData\Local\Programs\Python\Python38\lib\site-packages\requests\sessions.py", line 646, in send
    r = adapter.send(request, **kwargs)
  File "C:\Users\bwn\AppData\Local\Programs\Python\Python38\lib\site-packages\requests\adapters.py", line 498, in send
    raise ConnectionError(err, request=request)
requests.exceptions.ConnectionError: ('Connection aborted.', ConnectionResetError(10054, 'De externe host heeft een verbinding verbroken', None, 10054, None))


BTC Address: 1GruvoZ122mhmAxCKqAvaLdaaX8BWi52yG
Electrum Import Key: 5HrnS67uVnrKTi4oR1cg7eUpsSerEygWq2CrNpxP4KfahjrBLEJ
Private Key: 05abb6b28decf4e8d2104ffe0f7500abc651677b0431d84ffbf51a6b2d9ce239
Amount on address: 0
===========================================================
Traceback (most recent call last):
  File ".\BTCL-Dev-fastandbuggy.py", line 91, in <module>
    executeScript()
  File ".\BTCL-Dev-fastandbuggy.py", line 47, in executeScript
    btcamountinteger = int(btcamount)
UnboundLocalError: local variable 'btcamount' referenced before assignment

BTC Address: 1GruvoZ122mhmAxCKqAvaLdaaX8BWi52yG
Electrum Import Key: 5HrnS67uVnrKTi4oR1cg7eUpsSerEygWq2CrNpxP4KfahjrBLEJ
Private Key: 05abb6b28decf4e8d2104ffe0f7500abc651677b0431d84ffbf51a6b2d9ce239
Amount on address: 0
===========================================================
Traceback (most recent call last):
  File ".\BTCL-Dev-fastandbuggy.py", line 91, in <module>
    executeScript()
  File ".\BTCL-Dev-fastandbuggy.py", line 47, in executeScript
    btcamountinteger = int(btcamount)
UnboundLocalError: local variable 'btcamount' referenced before assignment
PS C:\Users\bwn\stack\code\BitcoinLottery>

BTC Address: 1vS7gU1coLkxdUdGnak1yDUmQx9vG8Cai
Electrum Import Key: 5JufXSwqxJkeAf6tQToGguAhVSEMEYf3mf9KY64HjzoTuVUenFs
Private Key: 8fe8860cb5b709952badc6deee693cd446b729de056c861eb56ff29e73635a07
Amount on address: 0
===========================================================
Traceback (most recent call last):
  File ".\BTCL-Dev-fastandbuggy.py", line 91, in <module>
    executeScript()
  File ".\BTCL-Dev-fastandbuggy.py", line 47, in executeScript
    btcamountinteger = int(btcamount)
UnboundLocalError: local variable 'btcamount' referenced before assignment